Workbook

Sheet January-26
A1: DAILY PRODUCTION 2026 | H1: MONTH OF JANUARY
A2: Date | B2: CHB 4''(10) | C2: CHB 6''(15) | D2: CHB 8''(20) | E2: HORDI 8'' | F2: INS 8'' | G2: HORDI10'' | H2: CHB30 | I2: INS 30 CM | J2: TOTAL | K2: REMARKS
A3: 1 | B3: 16060 | J3: =SUM(B3:I3) -> 16060
A4: 2 | J4: =SUM(B4:I4) -> 0 | K4: Friday
A5: 3 | C5: 4240 | D5: 8160 | J5: =SUM(B5:I5) -> 12400
A6: 4 | C6: 8800 | D6: 3852 | J6: =SUM(B6:I6) -> 12652
A7: 5 | C7: 5120 | D7: 8160 | J7: =SUM(B7:I7) -> 13280
A8: 6 | D8: 8340 | J8: =SUM(B8:I8) -> 8340
A9: 7 | D9: 8280 | J9: =SUM(B9:I9) -> 8280
A10: 8 | D10: 7740 | J10: =SUM(B10:I10) -> 7740
A11: 9 | J11: =SUM(B11:I11) -> 0 | K11: Friday
A12: 10 | C12: 11776 | J12: =SUM(B12:I12) -> 11776
A13: 11 | D13: 8172 | J13: =SUM(B13:I13) -> 8172
A14: 12 | C14: 5040 | D14: 8520 | J14: =SUM(B14:I14) -> 13560
A15: 13 | C15: 5424 | D15: 8220 | J15: =SUM(B15:I15) -> 13644
A16: 14 | D16: 8244 | J16: =SUM(B16:I16) -> 8244
A17: 15 | B17: 16192 | J17: =SUM(B17:I17) -> 16192
A18: 16 | J18: =SUM(B18:I18) -> 0 | K18: Friday
A19: 17 | D19: 7872 | J19: =SUM(B19:I19) -> 7872
A20: 18 | C20: 10640 | J20: =SUM(B20:I20) -> 10640
A21: 19 | D21: 8268 | J21: =SUM(B21:I21) -> 8268
A22: 20 | C22: 9440 | J22: =SUM(B22:I22) -> 9440
A23: 21 | D23: 8400 | J23: =SUM(B23:I23) -> 8400
A24: 22 | D24: 8580 | J24: =SUM(B24:I24) -> 8580
A25: 23 | J25: =SUM(B25:I25) -> 0 | K25: Friday
A26: 24 | D26: 8244 | J26: =SUM(B26:I26) -> 8244
A27: 25 | C27: 8400 | D27: 3528 | J27: =SUM(B27:I27) -> 11928
A28: 26 | D28: 8400 | J28: =SUM(B28:I28) -> 8400
A29: 27 | D29: 8220 | J29: =SUM(B29:I29) -> 8220
A30: 28 | C30: 10160 | J30: =SUM(B30:I30) -> 10160
A31: 29 | B31: 13750 | J31: =SUM(B31:I31) -> 13750
A32: 30 | J32: =SUM(B32:I32) -> 0 | K32: Friday
A33: 31 | D33: 8376 | J33: =SUM(B33:I33) -> 8376
B34: =SUM(B3:B33) -> 46002 | C34: =SUM(C3:C33) -> 79040 | D34: =SUM(D3:D33) -> 147576 | E34: =SUM(E3:E33) -> 0 | F34: =SUM(F3:F33) -> 0 | G34: =SUM(G3:G33) -> 0 | H34: =SUM(H3:H33) -> 0 | I34: =SUM(I3:I33) -> 0 | J34: =SUM(B34:I34) -> 272618
B35: =B34*1.9 -> 87403.8 | C35: =C34*1.95 -> 154128 | D35: =D34*2 -> 295152 | E35: =E34*2.2 -> 0 | F35: =F34*4.2 -> 0 | G35: =G34*2.7 -> 0 | H35: =H34*4 -> 0 | I35: =I34*5.2 -> 0 | J35: =SUM(B35:I35) -> 536683.8 | K35: =J35/J34 -> 1.9686294
B38: Item | D38: T Qnty | E38: Cement | F38: Gravel | G38: Sand | H38: T weigt | I38: Q Mtr | J38: Price/M3
B39: INS | D39: =F34 -> 0 | E39: =D39*2.17/1000 -> 0 | F39: =D39*13.33/1000 -> 0 | G39: =D39*5.83/1000 -> 0 | H39: =G39+F39+E39 -> 0 | I39: =D39/62.5 -> 0 | J39: =IFERROR(F35/I39,0) -> 0
B40: INS 30 | D40: =I34 -> 0 | E40: =D40*3.25/1000 -> 0 | F40: =D40*1.5*4.55/1000 -> 0 | G40: =D40*1.5*12.12/1000 -> 0 | H40: =G40+F40+E40 -> 0 | I40: =D40/41.625 -> 0 | J40: =IFERROR(F36/I40,0) -> 0
B41: 4" | D41: =B34 -> 46002 | E41: =D41*1.18/1000 -> 54.28236 | F41: =D41*7.27/1000 -> 334.43454 | G41: =D41*3.18/1000 -> 146.28636 | H41: =G41+F41+E41 -> 535.00326 | I41: =D41/125 -> 368.016 | J41: =B35/I41 -> 237.5
B42: 6" | D42: =C34 -> 79040 | E42: =D42*1.63/1000 -> 128.8352 | F42: =D42*10/1000 -> 790.4 | G42: =D42*4.4/1000 -> 347.776 | H42: =G42+F42+E42 -> 1267.0112 | I42: =D42/83.33 -> 948.51794 | J42: =C35/I42 -> 162.4935
...

Sheet February-26
A1: DAILY PRODUCTION 2026 | H1: MONTH OF FEBRUARY
A2: Date | B2: CHB 4''(10) | C2: CHB 6''(15) | D2: CHB 8''(20) | E2: HORDI 8'' | F2: INS 8'' | G2: HORDI10'' | H2: CHB30 | I2: INS 30 CM | J2: TOTAL | K2: REMARKS
A3: 1 | C3: 11872 | J3: =SUM(B3:I3) -> 11872
A4: 2 | D4: 8028 | J4: =SUM(B4:I4) -> 8028
A5: 3 | C5: 5040 | D5: 8208 | J5: =SUM(B5:I5) -> 13248
A6: 4 | D6: 8580 | J6: =SUM(B6:I6) -> 8580
A7: 5 | B7: 16170 | J7: =SUM(B7:I7) -> 16170
A8: 6 | J8: =SUM(B8:I8) -> 0 | K8: Friday
A9: 7 | C9: 1200 | D9: 5520 | J9: =SUM(B9:I9) -> 6720
A10: 8 | C10: 6720 | D10: 8832 | J10: =SUM(B10:I10) -> 15552
A11: 9 | D11: 6000 | J11: =SUM(B11:I11) -> 6000
A12: 10 | C12: 5040 | D12: 8136 | J12: =SUM(B12:I12) -> 13176
A13: 11 | D13: 10080 | J13: =SUM(B13:I13) -> 10080
A14: 12 | D14: 9480 | J14: =SUM(B14:I14) -> 9480
A15: 13 | J15: =SUM(B15:I15) -> 0 | K15: Friday
A16: 14 | C16: 6624 | D16: 10200 | J16: =SUM(B16:I16) -> 16824
A17: 15 | C17: 9984 | D17: 1260 | J17: =SUM(B17:I17) -> 11244
A18: 16 | D18: 10296 | J18: =SUM(B18:I18) -> 10296
A19: 17 | D19: 9180 | J19: =SUM(B19:I19) -> 9180
A20: 18 | D20: 10272 | J20: =SUM(B20:I20) -> 10272
A21: 19 | B21: 18084 | J21: =SUM(B21:I21) -> 18084
A22: 20 | J22: =SUM(B22:I22) -> 0 | K22: Friday
A23: 21 | C23: 12000 | J23: =SUM(B23:I23) -> 12000
A24: 22 | J24: =SUM(B24:I24) -> 0 | K24: F.Day
A25: 23 | C25: 5456 | D25: 10260 | J25: =SUM(B25:I25) -> 15716
A26: 24 | D26: 9300 | J26: =SUM(B26:I26) -> 9300
A27: 25 | C27: 5040 | D27: 8640 | J27: =SUM(B27:I27) -> 13680
A28: 26 | D28: 9240 | J28: =SUM(B28:I28) -> 9240
A29: 27 | J29: =SUM(B29:I29) -> 0 | K29: Friday
A30: 28 | C30: 11360 | J30: =SUM(B30:I30) -> 11360
A31: 29 | J31: =SUM(B31:I31) -> 0
A32: 30 | J32: =SUM(B32:I32) -> 0
A33: 31 | J33: =SUM(B33:I33) -> 0
B34: =SUM(B3:B33) -> 34254 | C34: =SUM(C3:C33) -> 80336 | D34: =SUM(D3:D33) -> 151512 | E34: =SUM(E3:E33) -> 0 | F34: =SUM(F3:F33) -> 0 | G34: =SUM(G3:G33) -> 0 | H34: =SUM(H3:H33) -> 0 | I34: =SUM(I3:I33) -> 0 | J34: =SUM(B34:I34) -> 266102
B35: =B34*1.9 -> 65082.6 | C35: =C34*1.95 -> 156655.2 | D35: =D34*2 -> 303024 | E35: =E34*2.2 -> 0 | F35: =F34*4.2 -> 0 | G35: =G34*2.7 -> 0 | H35: =H34*4 -> 0 | I35: =I34*5.2 -> 0 | J35: =SUM(B35:I35) -> 524761.8 | K35: =J35/J34 -> 1.9720325
B38: Item | D38: T Qnty | E38: Cement | F38: Gravel | G38: Sand | H38: T weigt | I38: Q Mtr | J38: Price/M3
B39: INS | D39: =F34 -> 0 | E39: =D39*2.17/1000 -> 0 | F39: =D39*13.33/1000 -> 0 | G39: =D39*5.83/1000 -> 0 | H39: =G39+F39+E39 -> 0 | I39: =D39/62.5 -> 0 | J39: =IFERROR(F35/I39,0) -> 0
B40: INS 30 | D40: =I34 -> 0 | E40: =D40*3.25/1000 -> 0 | F40: =D40*1.5*4.55/1000 -> 0 | G40: =D40*1.5*12.12/1000 -> 0 | H40: =G40+F40+E40 -> 0 | I40: =D40/41.625 -> 0 | J40: =IFERROR(F36/I40,0) -> 0
B41: 4" | D41: =B34 -> 34254 | E41: =D41*1.18/1000 -> 40.41972 | F41: =D41*7.27/1000 -> 249.02658 | G41: =D41*3.18/1000 -> 108.92772 | H41: =G41+F41+E41 -> 398.37402 | I41: =D41/125 -> 274.032 | J41: =B35/I41 -> 237.5
B42: 6" | D42: =C34 -> 80336 | E42: =D42*1.63/1000 -> 130.94768 | F42: =D42*10/1000 -> 803.36 | G42: =D42*4.4/1000 -> 353.4784 | H42: =G42+F42+E42 -> 1287.7861 | I42: =D42/83.33 -> 964.07056 | J42: =C35/I42 -> 162.4935
...

Sheet March-26
A1: DAILY PRODUCTION 2026 | H1: MONTH OF MARCH
A2: Date | B2: CHB 4''(10) | C2: CHB 6''(15) | D2: CHB 8''(20) | E2: HORDI 8'' | F2: INS 8'' | G2: HORDI10'' | H2: CHB30 | I2: INS 30 CM | J2: TOTAL | K2: REMARKS
A3: 1 | C3: 3520 | D3: 9300 | J3: =SUM(B3:I3) -> 12820
A4: 2 | D4: 9360 | J4: =SUM(B4:I4) -> 9360
A5: 3 | D5: 660 | J5: =SUM(B5:I5) -> 660 | K5: Rain
A6: 4 | D6: 10152 | J6: =SUM(B6:I6) -> 10152
A7: 5 | B7: 16280 | J7: =SUM(B7:I7) -> 16280
A8: 6 | J8: =SUM(B8:I8) -> 0 | K8: Friday
A9: 7 | D9: 9480 | J9: =SUM(B9:I9) -> 9480
A10: 8 | C10: 4960 | D10: 9060 | J10: =SUM(B10:I10) -> 14020
A11: 9 | D11: 9564 | J11: =SUM(B11:I11) -> 9564
A12: 10 | J12: =SUM(B12:I12) -> 0 | K12: Rain
A13: 11 | C13: 3872 | D13: 7908 | J13: =SUM(B13:I13) -> 11780
A14: 12 | C14: 4720 | D14: 8256 | J14: =SUM(B14:I14) -> 12976
A15: 13 | J15: =SUM(B15:I15) -> 0 | K15: Friday
A16: 14 | C16: 12128 | J16: =SUM(B16:I16) -> 12128
A17: 15 | D17: 9216 | J17: =SUM(B17:I17) -> 9216
A18: 16 | D18: 9240 | J18: =SUM(B18:I18) -> 9240
A19: 17 | D19: 8256 | J19: =SUM(B19:I19) -> 8256
A20: 18 | E20: 9480 | J20: =SUM(B20:I20) -> 9480
A21: 19 | J21: =SUM(B21:I21) -> 0 | K21: Off
A22: 20 | J22: =SUM(B22:I22) -> 0 | K22: Friday
A23: 21 | J23: =SUM(B23:I23) -> 0 | K23: Eid
A24: 22 | J24: =SUM(B24:I24) -> 0 | K24: Eid
A25: 23 | J25: =SUM(B25:I25) -> 0 | K25: Eid
A26: 24 | C26: 10480 | J26: =SUM(B26:I26) -> 10480
A27: 25 | C27: 6272 | J27: =SUM(B27:I27) -> 6272
A28: 26 | D28: 6912 | J28: =SUM(B28:I28) -> 6912
A29: 27 | J29: =SUM(B29:I29) -> 0 | K29: Friday
A30: 28 | D30: 9120 | J30: =SUM(B30:I30) -> 9120
A31: 29 | D31: 9264 | J31: =SUM(B31:I31) -> 9264
A32: 30 | C32: 11440 | J32: =SUM(B32:I32) -> 11440
A33: 31 | D33: 8124 | J33: =SUM(B33:I33) -> 8124
B34: =SUM(B3:B33) -> 16280 | C34: =SUM(C3:C33) -> 57392 | D34: =SUM(D3:D33) -> 133872 | E34: =SUM(E3:E33) -> 9480 | F34: =SUM(F3:F33) -> 0 | G34: =SUM(G3:G33) -> 0 | H34: =SUM(H3:H33) -> 0 | I34: =SUM(I3:I33) -> 0 | J34: =SUM(B34:I34) -> 217024
B35: =B34*1.9 -> 30932 | C35: =C34*1.95 -> 111914.4 | D35: =D34*2 -> 267744 | E35: =E34*2.2 -> 20856 | F35: =F34*4.2 -> 0 | G35: =G34*2.7 -> 0 | H35: =H34*4 -> 0 | I35: =I34*5.2 -> 0 | J35: =SUM(B35:I35) -> 431446.4 | K35: =J35/J34 -> 1.9880124
B38: Item | D38: T Qnty | E38: Cement | F38: Gravel | G38: Sand | H38: T weigt | I38: Q Mtr | J38: Price/M3
B39: INS | D39: =F34 -> 0 | E39: =D39*2.17/1000 -> 0 | F39: =D39*13.33/1000 -> 0 | G39: =D39*5.83/1000 -> 0 | H39: =G39+F39+E39 -> 0 | I39: =D39/62.5 -> 0 | J39: =IFERROR(F35/I39,0) -> 0
B40: INS 30 | D40: =I34 -> 0 | E40: =D40*3.25/1000 -> 0 | F40: =D40*1.5*4.55/1000 -> 0 | G40: =D40*1.5*12.12/1000 -> 0 | H40: =G40+F40+E40 -> 0 | I40: =D40/41.625 -> 0 | J40: =IFERROR(F36/I40,0) -> 0
B41: 4" | D41: =B34 -> 16280 | E41: =D41*1.18/1000 -> 19.2104 | F41: =D41*7.27/1000 -> 118.3556 | G41: =D41*3.18/1000 -> 51.7704 | H41: =G41+F41+E41 -> 189.3364 | I41: =D41/125 -> 130.24 | J41: =B35/I41 -> 237.5
B42: 6" | D42: =C34 -> 57392 | E42: =D42*1.63/1000 -> 93.54896 | F42: =D42*10/1000 -> 573.92 | G42: =D42*4.4/1000 -> 252.5248 | H42: =G42+F42+E42 -> 919.99376 | I42: =D42/83.33 -> 688.73155 | J42: =C35/I42 -> 162.4935
...

Sheet April-26
A1: DAILY PRODUCTION 2026 | H1: MONTH OF APRIL
A2: Date | B2: CHB 4''(10) | C2: CHB 6''(15) | D2: CHB 8''(20) | E2: HORDI 8'' | F2: INS 8'' | G2: HORDI10'' | H2: CHB30 | I2: INS 30 CM | J2: TOTAL | K2: REMARKS
A3: 1 | D3: 9420 | F3: 0 | J3: =SUM(B3:I3) -> 9420
A4: 2 | B4: 12870 | C4: 3040 | J4: =SUM(B4:I4) -> 15910
A5: 3 | J5: =SUM(B5:I5) -> 0 | K5: Friday
A6: 4 | D6: 9228 | J6: =SUM(B6:I6) -> 9228
A7: 5 | D7: 9204 | J7: =SUM(B7:I7) -> 9204
A8: 6 | D8: 9540 | J8: =SUM(B8:I8) -> 9540
A9: 7 | C9: 6240 | J9: =SUM(B9:I9) -> 6240
A10: 8 | D10: 4800 | J10: =SUM(B10:I10) -> 4800
A11: 9 | D11: 8640 | J11: =SUM(B11:I11) -> 8640
A12: 10 | J12: =SUM(B12:I12) -> 0 | K12: Friday
A13: 11 | B13: 0 | D13: 9300 | J13: =SUM(B13:I13) -> 9300
A14: 12 | B14: 0 | C14: 2720 | D14: 7200 | J14: =SUM(B14:I14) -> 9920
A15: 13 | C15: 8400 | D15: 4800 | J15: =SUM(B15:I15) -> 13200
A16: 14 | C16: 4960 | D16: 9048 | J16: =SUM(B16:I16) -> 14008
A17: 15 | B17: 0 | C17: 5040 | D17: 8460 | J17: =SUM(B17:I17) -> 13500
A18: 16 | B18: 14630 | J18: =SUM(B18:I18) -> 14630
A19: 17 | J19: =SUM(B19:I19) -> 0 | K19: Friday
A20: 18 | D20: 8364 | J20: =SUM(B20:I20) -> 8364
A21: 19 | D21: 9276 | J21: =SUM(B21:I21) -> 9276
A22: 20 | D22: 9300 | J22: =SUM(B22:I22) -> 9300
A23: 21 | D23: 9336 | J23: =SUM(B23:I23) -> 9336
A24: 22 | C24: 9360 | J24: =SUM(B24:I24) -> 9360
A25: 23 | F25: 2844 | J25: =SUM(B25:I25) -> 2844
A26: 24 | J26: =SUM(B26:I26) -> 0 | K26: Friday
A27: 25 | C27: 3040 | D27: 9456 | J27: =SUM(B27:I27) -> 12496
A28: 26 | C28: 2304 | D28: 8184 | J28: =SUM(B28:I28) -> 10488
A29: 27 | D29: 9336 | J29: =SUM(B29:I29) -> 9336
A30: 28 | C30: 3360 | D30: 10344 | J30: =SUM(B30:I30) -> 13704
A31: 29 | C31: 3072 | D31: 8148 | J31: =SUM(B31:I31) -> 11220
A32: 30 | F32: 5820 | J32: =SUM(B32:I32) -> 5820
A33: 31 | J33: =SUM(B33:I33) -> 0
B34: =SUM(B3:B33) -> 27500 | C34: =SUM(C3:C33) -> 51536 | D34: =SUM(D3:D33) -> 171384 | E34: =SUM(E3:E33) -> 0 | F34: =SUM(F3:F33) -> 8664 | G34: =SUM(G3:G33) -> 0 | H34: =SUM(H3:H33) -> 0 | I34: =SUM(I3:I33) -> 0 | J34: =SUM(B34:I34) -> 259084
B35: =B34*1.9 -> 52250 | C35: =C34*1.95 -> 100495.2 | D35: =D34*2 -> 342768 | E35: =E34*2.2 -> 0 | F35: =F34*4.75 -> 41154 | G35: =G34*2.7 -> 0 | H35: =H34*4 -> 0 | I35: =I34*5.2 -> 0 | J35: =SUM(B35:I35) -> 536667.2 | K35: =J35/J34 -> 2.0714023
B38: Item | D38: T Qnty | E38: Cement | F38: Gravel | G38: Sand | H38: T weigt | I38: Q Mtr | J38: Price/M3
B39: INS | D39: =F34 -> 8664 | E39: =D39*2.17/1000 -> 18.80088 | F39: =D39*13.33/1000 -> 115.49112 | G39: =D39*5.83/1000 -> 50.51112 | H39: =G39+F39+E39 -> 184.80312 | I39: =D39/62.5 -> 138.624 | J39: =IFERROR(F35/I39,0) -> 296.875
B40: INS 30 | D40: =I34 -> 0 | E40: =D40*3.25/1000 -> 0 | F40: =D40*1.5*4.55/1000 -> 0 | G40: =D40*1.5*12.12/1000 -> 0 | H40: =G40+F40+E40 -> 0 | I40: =D40/41.625 -> 0 | J40: =IFERROR(F36/I40,0) -> 0
B41: 4" | D41: =B34 -> 27500 | E41: =D41*1.18/1000 -> 32.45 | F41: =D41*7.27/1000 -> 199.925 | G41: =D41*3.18/1000 -> 87.45 | H41: =G41+F41+E41 -> 319.825 | I41: =D41/125 -> 220 | J41: =IFERROR(F37/I41,0) -> 0
B42: 6" | D42: =C34 -> 51536 | E42: =D42*1.63/1000 -> 84.00368 | F42: =D42*10/1000 -> 515.36 | G42: =D42*4.4/1000 -> 226.7584 | H42: =G42+F42+E42 -> 826.12208 | I42: =D42/83.33 -> 618.45674 | J42: =IFERROR(F38/I42,0) -> 0
...

Sheet May-26
A1: DAILY PRODUCTION 2026 | H1: MONTH OF MAY
A2: Date | B2: CHB 4''(10) | C2: CHB 6''(15) | D2: CHB 8''(20) | E2: HORDI 8'' | F2: INS 8'' | G2: HORDI10'' | H2: CHB30 | I2: INS 30 CM | J2: TOTAL | K2: REMARKS
A3: 1 | J3: =SUM(B3:I3) -> 0 | K3: Friday
A4: 2 | C4: 3056 | D4: 9516 | J4: =SUM(B4:I4) -> 12572
A5: 3 | C5: 3392 | D5: 10032 | J5: =SUM(B5:I5) -> 13424
A6: 4 | C6: 3168 | D6: 9396 | J6: =SUM(B6:I6) -> 12564
A7: 5 | C7: 3040 | D7: 9240 | J7: =SUM(B7:I7) -> 12280
A8: 6 | C8: 3168 | D8: 7944 | J8: =SUM(B8:I8) -> 11112
A9: 7 | B9: 15070 | J9: =SUM(B9:I9) -> 15070
A10: 8 | J10: =SUM(B10:I10) -> 0 | K10: Friday
A11: 9 | C11: 3536 | D11: 10416 | J11: =SUM(B11:I11) -> 13952
A12: 10 | C12: 1200 | D12: 7476 | J12: =SUM(B12:I12) -> 8676
A13: 11 | C13: 3760 | D13: 8988 | J13: =SUM(B13:I13) -> 12748
A14: 12 | C14: 2752 | D14: 9288 | J14: =SUM(B14:I14) -> 12040
A15: 13 | C15: 4464 | D15: 9336 | J15: =SUM(B15:I15) -> 13800
A16: 14 | D16: 9240 | J16: =SUM(B16:I16) -> 9240
A17: 15 | J17: =SUM(B17:I17) -> 0 | K17: Friday
A18: 16 | C18: 4112 | D18: 9288 | J18: =SUM(B18:I18) -> 13400
A19: 17 | C19: 3168 | D19: 8268 | J19: =SUM(B19:I19) -> 11436
A20: 18 | C20: 3504 | D20: 7884 | J20: =SUM(B20:I20) -> 11388
A21: 19 | C21: 3264 | D21: 8220 | J21: =SUM(B21:I21) -> 11484
A22: 20 | C22: 3600 | D22: 8244 | J22: =SUM(B22:I22) -> 11844
A23: 21 | F23: 7332 | J23: =SUM(B23:I23) -> 7332
A24: 22 | J24: =SUM(B24:I24) -> 0 | K24: Friday
A25: 23 | C25: 2688 | D25: 8220 | J25: =SUM(B25:I25) -> 10908
A26: 24 | C26: 4560 | D26: 9300 | J26: =SUM(B26:I26) -> 13860
A27: 25 | B27: 16544 | J27: =SUM(B27:I27) -> 16544
A28: 26 | J28: =SUM(B28:I28) -> 0 | K28: Eid
A29: 27 | J29: =SUM(B29:I29) -> 0 | K29: Eid
A30: 28 | J30: =SUM(B30:I30) -> 0 | K30: Eid
A31: 29 | J31: =SUM(B31:I31) -> 0 | K31: Friday
A32: 30 | J32: =SUM(B32:I32) -> 0 | K32: Eid
A33: 31 | C33: 3200 | D33: 9348 | J33: =SUM(B33:I33) -> 12548
B34: =SUM(B3:B33) -> 31614 | C34: =SUM(C3:C33) -> 59632 | D34: =SUM(D3:D33) -> 169644 | E34: =SUM(E3:E33) -> 0 | F34: =SUM(F3:F33) -> 7332 | G34: =SUM(G3:G33) -> 0 | H34: =SUM(H3:H33) -> 0 | I34: =SUM(I3:I33) -> 0 | J34: =SUM(B34:I34) -> 268222
B35: =B34*1.9 -> 60066.6 | C35: =C34*1.95 -> 116282.4 | D35: =D34*2 -> 339288 | E35: =E34*2.2 -> 0 | F35: =F34*4.2 -> 30794.4 | G35: =G34*2.7 -> 0 | H35: =H34*4 -> 0 | I35: =I34*5.2 -> 0 | J35: =SUM(B35:I35) -> 546431.4 | K35: =J35/J34 -> 2.0372356
B38: Item | D38: T Qnty | E38: Cement | F38: Gravel | G38: Sand | H38: T weigt | I38: Q Mtr | J38: Price/M3
B39: INS | D39: =F34 -> 7332 | E39: =D39*2.17/1000 -> 15.91044 | F39: =D39*13.33/1000 -> 97.73556 | G39: =D39*5.83/1000 -> 42.74556 | H39: =G39+F39+E39 -> 156.39156 | I39: =D39/62.5 -> 117.312 | J39: =IFERROR(F35/I39,0) -> 262.5
B40: INS 30 | D40: =I34 -> 0 | E40: =D40*3.25/1000 -> 0 | F40: =D40*1.5*4.55/1000 -> 0 | G40: =D40*1.5*12.12/1000 -> 0 | H40: =G40+F40+E40 -> 0 | I40: =D40/41.625 -> 0 | J40: =IFERROR(F36/I40,0) -> 0
B41: 4" | D41: =B34 -> 31614 | E41: =D41*1.18/1000 -> 37.30452 | F41: =D41*7.27/1000 -> 229.83378 | G41: =D41*3.18/1000 -> 100.53252 | H41: =G41+F41+E41 -> 367.67082 | I41: =D41/125 -> 252.912 | J41: =IFERROR(F37/I41,0) -> 0
B42: 6" | D42: =C34 -> 59632 | E42: =D42*1.63/1000 -> 97.20016 | F42: =D42*10/1000 -> 596.32 | G42: =D42*4.4/1000 -> 262.3808 | H42: =G42+F42+E42 -> 955.90096 | I42: =D42/83.33 -> 715.61262 | J42: =IFERROR(F38/I42,0) -> 0
...

Sheet June-26
A1: DAILY PRODUCTION 2026 | H1: MONTH OF JUNE
A2: Date | B2: CHB 4''(10) | C2: CHB 6''(15) | D2: CHB 8''(20) | E2: HORDI 8'' | F2: INS 8'' | G2: HORDI10'' | H2: CHB30 | I2: INS 30 CM | J2: TOTAL | K2: REMARKS
A3: 1 | C3: 4640 | D3: 9396 | J3: =SUM(B3:I3) -> 14036
A4: 2 | D4: 9348 | J4: =SUM(B4:I4) -> 9348
A5: 3 | C5: 880 | D5: 8616 | J5: =SUM(B5:I5) -> 9496
A6: 4 | D6: 9336 | J6: =SUM(B6:I6) -> 9336
A7: 5 | J7: =SUM(B7:I7) -> 0 | K7: Friday
A8: 6 | C8: 4544 | D8: 9360 | J8: =SUM(B8:I8) -> 13904
A9: 7 | D9: 9420 | J9: =SUM(B9:I9) -> 9420
A10: 8 | C10: 4752 | D10: 10272 | J10: =SUM(B10:I10) -> 15024
A11: 9 | C11: 3168 | D11: 9264 | J11: =SUM(B11:I11) -> 12432
A12: 10 | C12: 2880 | D12: 9240 | J12: =SUM(B12:I12) -> 12120
A13: 11 | B13: 16874 | J13: =SUM(B13:I13) -> 16874
A14: 12 | J14: =SUM(B14:I14) -> 0 | K14: Friday
A15: 13 | D15: 9216 | J15: =SUM(B15:I15) -> 9216
A16: 14 | C16: 3888 | D16: 8220 | J16: =SUM(B16:I16) -> 12108
A17: 15 | C17: 5040 | D17: 8232 | J17: =SUM(B17:I17) -> 13272
A18: 16 | C18: 4688 | D18: 8268 | J18: =SUM(B18:I18) -> 12956
A19: 17 | C19: 1664 | D19: 5952 | J19: =SUM(B19:I19) -> 7616
A20: 18 | B20: 15642 | J20: =SUM(B20:I20) -> 15642
A21: 19 | J21: =SUM(B21:I21) -> 0 | K21: Friday
A22: 20 | C22: 5088 | D22: 9324 | J22: =SUM(B22:I22) -> 14412
A23: 21 | C23: 4704 | D23: 9084 | J23: =SUM(B23:I23) -> 13788
A24: 22 | C24: 5040 | D24: 9180 | J24: =SUM(B24:I24) -> 14220
A25: 23 | C25: 4160 | D25: 6660 | J25: =SUM(B25:I25) -> 10820
A26: 24 | C26: 4400 | D26: 8040 | J26: =SUM(B26:I26) -> 12440
A27: 25 | D27: 9408 | J27: =SUM(B27:I27) -> 9408
A28: 26 | J28: =SUM(B28:I28) -> 0 | K28: Friday
A29: 27 | C29: 4784 | D29: 7488 | J29: =SUM(B29:I29) -> 12272
A30: 28 | D30: 9300 | J30: =SUM(B30:I30) -> 9300
A31: 29 | C31: 4912 | D31: 8400 | J31: =SUM(B31:I31) -> 13312
A32: 30 | C32: 4832 | D32: 9060 | J32: =SUM(B32:I32) -> 13892
A33: 31 | J33: =SUM(B33:I33) -> 0
B34: =SUM(B3:B33) -> 32516 | C34: =SUM(C3:C33) -> 74064 | D34: =SUM(D3:D33) -> 210084 | E34: =SUM(E3:E33) -> 0 | F34: =SUM(F3:F33) -> 0 | G34: =SUM(G3:G33) -> 0 | H34: =SUM(H3:H33) -> 0 | I34: =SUM(I3:I33) -> 0 | J34: =SUM(B34:I34) -> 316664
B35: =B34*1.9 -> 61780.4 | C35: =C34*1.95 -> 144424.8 | D35: =D34*2 -> 420168 | E35: =E34*2.2 -> 0 | F35: =F34*4.2 -> 0 | G35: =G34*2.7 -> 0 | H35: =H34*4 -> 0 | I35: =I34*5.2 -> 0 | J35: =SUM(B35:I35) -> 626373.2 | K35: =J35/J34 -> 1.9780373
B38: Item | D38: T Qnty | E38: Cement | F38: Gravel | G38: Sand | H38: T weigt | I38: Q Mtr | J38: Price/M3
B39: INS | D39: =F34 -> 0 | E39: =D39*2.17/1000 -> 0 | F39: =D39*13.33/1000 -> 0 | G39: =D39*5.83/1000 -> 0 | H39: =G39+F39+E39 -> 0 | I39: =D39/62.5 -> 0 | J39: =IFERROR(F35/I39,0) -> 0
B40: INS 30 | D40: =I34 -> 0 | E40: =D40*3.25/1000 -> 0 | F40: =D40*1.5*4.55/1000 -> 0 | G40: =D40*1.5*12.12/1000 -> 0 | H40: =G40+F40+E40 -> 0 | I40: =D40/41.625 -> 0 | J40: =IFERROR(F36/I40,0) -> 0
B41: 4" | D41: =B34 -> 32516 | E41: =D41*1.274/1000 -> 41.425384 | F41: =D41*7.27/1000 -> 236.39132 | G41: =D41*3.18/1000 -> 103.40088 | H41: =G41+F41+E41 -> 381.21758 | I41: =D41/125 -> 260.128 | J41: =IFERROR(F37/I41,0) -> 0
B42: 6" | D42: =C34 -> 74064 | E42: =D42*1.89/1000 -> 139.98096 | F42: =D42*10/1000 -> 740.64 | G42: =D42*4.4/1000 -> 325.8816 | H42: =G42+F42+E42 -> 1206.5026 | I42: =D42/83.33 -> 888.80355 | J42: =IFERROR(F38/I42,0) -> 0
...

Sheet July-26
A1: DAILY PRODUCTION 2026 | H1: MONTH OF JULY
A2: Date | B2: CHB 4''(10) | C2: CHB 6''(15) | D2: CHB 8''(20) | E2: HORDI 8'' | F2: INS 8'' | G2: HORDI10'' | H2: CHB30 | I2: INS 30 CM | J2: TOTAL | K2: REMARKS
A3: 1 | C3: 4336 | D3: 8100 | J3: =SUM(B3:I3) -> 12436
A4: 2 | B4: 15026 | J4: =SUM(B4:I4) -> 15026
A5: 3 | J5: =SUM(B5:I5) -> 0 | K5: Friday
A6: 4 | D6: 9240 | J6: =SUM(B6:I6) -> 9240
A7: 5 | C7: 4352 | D7: 9072 | J7: =SUM(B7:I7) -> 13424
A8: 6 | C8: 4560 | D8: 8328 | J8: =SUM(B8:I8) -> 12888
A9: 7 | C9: 2720 | D9: 7260 | J9: =SUM(B9:I9) -> 9980
A10: 8 | D10: 7920 | J10: =SUM(B10:I10) -> 7920
A11: 9 | F11: 5664 | J11: =SUM(B11:I11) -> 5664
A12: 10 | J12: =SUM(B12:I12) -> 0 | K12: Friday
A13: 11 | C13: 4032 | D13: 9120 | J13: =SUM(B13:I13) -> 13152
A14: 12 | C14: 3712 | D14: 8100 | J14: =SUM(B14:I14) -> 11812
A15: 13 | D15: 9240 | J15: =SUM(B15:I15) -> 9240
A16: 14 | C16: 2880 | D16: 9048 | J16: =SUM(B16:I16) -> 11928
A17: 15 | C17: 3264 | D17: 7980 | J17: =SUM(B17:I17) -> 11244
A18: 16 | F18: 4248 | J18: =SUM(B18:I18) -> 4248
A19: 17 | J19: =SUM(B19:I19) -> 0 | K19: Friday
A20: 18 | C20: 3968 | D20: 8124 | J20: =SUM(B20:I20) -> 12092
A21: 19 | D21: 8988 | J21: =SUM(B21:I21) -> 8988
A22: 20 | C22: 3072 | D22: 6000 | J22: =SUM(B22:I22) -> 9072
A23: 21 | C23: 4160 | D23: 4140 | J23: =SUM(B23:I23) -> 8300
A24: 22 | C24: 2432 | D24: 7920 | J24: =SUM(B24:I24) -> 10352
A25: 23 | C25: 0 | D25: 8268 | J25: =SUM(B25:I25) -> 8268
A26: 24 | J26: =SUM(B26:I26) -> 0 | K26: Friday
A27: 25 | C27: 4208 | D27: 8064 | J27: =SUM(B27:I27) -> 12272
A28: 26 | C28: 1440 | D28: 8172 | J28: =SUM(B28:I28) -> 9612
A29: 27 | C29: 3328 | D29: 8028 | J29: =SUM(B29:I29) -> 11356
A30: 28 | C30: 2256 | D30: 8268 | J30: =SUM(B30:I30) -> 10524
A31: 29 | D31: 8028 | J31: =SUM(B31:I31) -> 8028
A32: 30 | B32: 1760 | C32: 9184 | J32: =SUM(B32:I32) -> 10944
A33: 31 | J33: =SUM(B33:I33) -> 0 | K33: Friday
B34: =SUM(B3:B33) -> 16786 | C34: =SUM(C3:C33) -> 63904 | D34: =SUM(D3:D33) -> 177408 | E34: =SUM(E3:E33) -> 0 | F34: =SUM(F3:F33) -> 9912 | G34: =SUM(G3:G33) -> 0 | H34: =SUM(H3:H33) -> 0 | I34: =SUM(I3:I33) -> 0 | J34: =SUM(B34:I34) -> 268010
B35: =B34*1.9 -> 31893.4 | C35: =C34*1.95 -> 124612.8 | D35: =D34*2 -> 354816 | E35: =E34*2.2 -> 0 | F35: =F34*4.75 -> 47082 | G35: =G34*2.7 -> 0 | H35: =H34*4 -> 0 | I35: =I34*5.2 -> 0 | J35: =SUM(B35:I35) -> 558404.2 | K35: =J35/J34 -> 2.08352
B38: Item | D38: T Qnty | E38: Cement | F38: Gravel | G38: Sand | H38: T weigt | I38: Q Mtr | J38: Price/M3
B39: INS | D39: =F34 -> 9912 | E39: =D39*2.17/1000 -> 21.50904 | F39: =D39*13.33/1000 -> 132.12696 | G39: =D39*5.83/1000 -> 57.78696 | H39: =G39+F39+E39 -> 211.42296 | I39: =D39/62.5 -> 158.592 | J39: =IFERROR(F35/I39,0) -> 296.875
B40: INS 30 | D40: =I34 -> 0 | E40: =D40*3.25/1000 -> 0 | F40: =D40*1.5*4.55/1000 -> 0 | G40: =D40*1.5*12.12/1000 -> 0 | H40: =G40+F40+E40 -> 0 | I40: =D40/41.625 -> 0 | J40: =IFERROR(F36/I40,0) -> 0
B41: 4" | D41: =B34 -> 16786 | E41: =D41*1.18/1000 -> 19.80748 | F41: =D41*7.27/1000 -> 122.03422 | G41: =D41*3.18/1000 -> 53.37948 | H41: =G41+F41+E41 -> 195.22118 | I41: =D41/125 -> 134.288 | J41: =IFERROR(F37/I41,0) -> 0
B42: 6" | D42: =C34 -> 63904 | E42: =D42*1.63/1000 -> 104.16352 | F42: =D42*10/1000 -> 639.04 | G42: =D42*4.4/1000 -> 281.1776 | H42: =G42+F42+E42 -> 1024.3811 | I42: =D42/83.33 -> 766.87868 | J42: =IFERROR(F38/I42,0) -> 0
...

Sheet Year-2026
A1: TOTAL PRODUCTION OF YEAR 2026
A2: Month | B2: CHB 4''(10) | C2: CHB 6''(15) | D2: CHB 8''(20) | E2: Hordi 8'' | F2: INS 8''(20) | G2: Hordi 10'' | H2: CHB 30 | I2: INS30 CM | J2: Monthly
A3: January | B3: ='January-26'!B34 -> 46002 | C3: ='January-26'!C34 -> 79040 | D3: ='January-26'!D34 -> 147576 | E3: ='January-26'!E34 -> 0 | F3: ='January-26'!F34 -> 0 | G3: ='January-26'!G34 -> 0 | H3: ='January-26'!H34 -> 0 | I3: ='January-26'!I34 -> 0 | J3: =SUM(B3:I3) -> 272618 | W3: Product | X3: Total Production
A4: February | B4: ='February-26'!B34 -> 34254 | C4: ='February-26'!C34 -> 80336 | D4: ='February-26'!D34 -> 151512 | E4: ='February-26'!E34 -> 0 | F4: ='February-26'!F34 -> 0 | G4: ='February-26'!G34 -> 0 | H4: ='February-26'!H34 -> 0 | I4: ='February-26'!I34 -> 0 | J4: =SUM(B4:I4) -> 266102 | M4: Month | N4: Total Production | W4: CHB 8''(20) | X4: =D15 -> 1161480
A5: March | B5: ='March-26'!B34 -> 16280 | C5: ='March-26'!C34 -> 57392 | D5: ='March-26'!D34 -> 133872 | E5: ='March-26'!E34 -> 9480 | F5: ='March-26'!F34 -> 0 | G5: ='March-26'!G34 -> 0 | H5: ='March-26'!H34 -> 0 | I5: ='March-26'!I34 -> 0 | J5: =SUM(B5:I5) -> 217024 | M5: Jan | N5: ='January-26'!J34 -> 272618 | W5: CHB 6''(15) | X5: =C15 -> 465904
A6: April | B6: ='April-26'!B34 -> 27500 | C6: ='April-26'!C34 -> 51536 | D6: ='April-26'!D34 -> 171384 | E6: ='April-26'!E34 -> 0 | F6: ='April-26'!F34 -> 8664 | G6: ='April-26'!G34 -> 0 | H6: ='April-26'!H34 -> 0 | I6: ='April-26'!I34 -> 0 | J6: =SUM(B6:I6) -> 259084 | M6: Feb | N6: ='February-26'!J34 -> 266102 | W6: CHB 4''(10) | X6: =B15 -> 204952
A7: May | B7: ='May-26'!B34 -> 31614 | C7: ='May-26'!C34 -> 59632 | D7: ='May-26'!D34 -> 169644 | E7: ='May-26'!E34 -> 0 | F7: ='May-26'!F34 -> 7332 | G7: ='May-26'!G34 -> 0 | H7: ='May-26'!H34 -> 0 | I7: ='May-26'!I34 -> 0 | J7: =SUM(B7:I7) -> 268222 | M7: Mar | N7: ='March-26'!J34 -> 217024 | W7: INS 8''(20) | X7: =F15 -> 25908
A8: June | B8: ='June-26'!B34 -> 32516 | C8: ='June-26'!C34 -> 74064 | D8: ='June-26'!D34 -> 210084 | E8: ='June-26'!E34 -> 0 | F8: ='June-26'!F34 -> 0 | G8: ='June-26'!G34 -> 0 | H8: ='June-26'!H34 -> 0 | I8: ='June-26'!I34 -> 0 | J8: =SUM(B8:I8) -> 316664 | M8: Apr | N8: ='April-26'!J34 -> 259084 | W8: Hordi 8" | X8: =E15 -> 9480
A9: July | B9: ='July-26'!B34 -> 16786 | C9: ='July-26'!C34 -> 63904 | D9: ='July-26'!D34 -> 177408 | E9: ='July-26'!E34 -> 0 | F9: ='July-26'!F34 -> 9912 | G9: ='July-26'!G34 -> 0 | H9: ='July-26'!H34 -> 0 | I9: ='July-26'!I34 -> 0 | J9: =SUM(B9:I9) -> 268010 | M9: May | N9: ='May-26'!J34 -> 268222
A10: August | J10: =SUM(B10:I10) -> 0 | M10: Jun | N10: ='June-26'!J34 -> 316664
A11: September | J11: =SUM(B11:I11) -> 0 | M11: Jul | N11: ='July-26'!J34 -> 268010
A12: Octoer | J12: =SUM(B12:I12) -> 0
A13: November | J13: =SUM(B13:I13) -> 0 | P13: Note: Data is current through July 2026. Production figures will be updated as additional monthly data becomes available.
A14: December | J14: =SUM(B14:I14) -> 0
A15: Total qnty. | B15: =SUM(B3:B14) -> 204952 | C15: =SUM(C3:C14) -> 465904 | D15: =SUM(D3:D14) -> 1161480 | E15: =SUM(E3:E14) -> 9480 | F15: =SUM(F3:F14) -> 25908 | G15: =SUM(G3:G14) -> 0 | H15: =SUM(H3:H14) -> 0 | I15: =SUM(I3:I14) -> 0 | J15: =SUM(B15:I15) -> 1867724
A16: Total M3. | B16: =B15/125 -> 1639.616 | C16: =C15/83.33 -> 5591.0716 | D16: =D15/62.5 -> 18583.68 | E16: =E15/62.5 -> 151.68 | F16: =F15/62.5 -> 414.528 | G16: =G15/50 -> 0 | H16: =H15/41.63 -> 0 | I16: =I15/41.63 -> 0 | J16: =SUM(B16:I16) -> 26380.576
A17: Total value | B17: =B15*1.6 -> 327923.2 | C17: =C15*1.65 -> 768741.6 | D17: =D15*1.7 -> 1974516 | E17: =E15*1.8 -> 17064 | F17: =F15*3.8 -> 98450.4 | G17: =G15*3.8 -> 0 | H17: =H15*3.5 -> 0 | I17: =I15*5.2 -> 0 | J17: =SUM(B17:I17) -> 3186695.2
V18: Insight: CHB 8"(20) is the highest-produced product during 2026, followed by CHB 6"(15). INS 8"(20) and Hordi 8" contribute a smaller share of total production.
A21: Insulated B
A22: Total Qnty | B22: Total M3 | C22: Total price | D22: Avarage/ Unit
A23: =F15+I15 -> 25908 | B23: =F16+I16 -> 414.528 | C23: =F17+I17 -> 98450.4 | D23: =IFERROR(C23/B23,0) -> 237.5
A25: CHB
A26: Total Qnty | B26: Total M3 | C26: Total price | D26: Avarage/Unit
A27: =B15+C15+D15+E15+G15+H15 -> 1841816 | B27: =B16+C16+D16+E16+G16+H16 -> 25966.048 | C27: =B17+C17+D17+E17+G17+H17 -> 3088244.8 | D27: =C27/B27 -> 118.93396
L28: Note: Data is current through 21 July 2026. August–December are future reporting periods and will be updated as production data becomes available.
A29: Item | B29: Gravel | C29: M3 | D29: Sand | E29: M3 | F29: Cement | G29: Ton | H29: Total Wt in Kg
A30: CHB 4(10) | B30: =B15*7.27 -> 1490001 | C30: =B30/1680 -> 886.90538 | D30: =B15*3.18 -> 651747.36 | E30: =D30/1600 -> 407.3421 | F30: =B15*1.18 -> 241843.36 | G30: =F30/1000 -> 241.84336 | H30: =B30+D30+F30 -> 2383591.8
A31: CHB6(15) | B31: =C15*10 -> 4659040 | C31: =B31/1680 -> 2773.2381 | D31: =C15*4.4 -> 2049977.6 | E31: =D31/1600 -> 1281.236 | F31: =C15*1.63 -> 759423.52 | G31: =F31/1000 -> 759.42352 | H31: =B31+D31+F31 -> 7468441.1
A32: CHB8(20) | B32: =D15*11.11 -> 12904043 | C32: =B32/1680 -> 7680.9779 | D32: =D15*4.86 -> 5644792.8 | E32: =D32/1600 -> 3527.9955 | F32: =D15*1.81 -> 2102278.8 | G32: =F32/1000 -> 2102.2788 | H32: =B32+D32+F32 -> 20651114
A33: Hordi 8'' | B33: =E15*10.26 -> 97264.8 | C33: =B33/1680 -> 57.895714 | D33: =E15*4.49 -> 42565.2 | E33: =D33/1600 -> 26.60325 | F33: =E15*1.67 -> 15831.6 | G33: =F33/1000 -> 15.8316 | H33: =B33+D33+F33 -> 155661.6
A34: INS 8'' | B34: =F15*13.33 -> 345353.64 | C34: =B34/1680 -> 205.56764 | D34: =F15*5.83 -> 151043.64 | E34: =D34/1600 -> 94.402275 | F34: =F15*2.17 -> 56220.36 | G34: =F34/1000 -> 56.22036 | H34: =B34+D34+F34 -> 552617.64
A35: CHB 30 | B35: =H15*16.67 -> 0 | C35: =B35/1680 -> 0 | D35: =H15*7.29 -> 0 | E35: =D35/1600 -> 0 | F35: =H15*2.17 -> 0 | G35: =F35/1000 -> 0 | H35: =B35+D35+F35 -> 0
A36: INS 30 | B36: =I15*20 -> 0 | C36: =B36/1680 -> 0 | D36: =I15*8.75 -> 0 | E36: =D36/1600 -> 0 | F36: =I15*3.25 -> 0 | G36: =F36/1000 -> 0 | H36: =B36+D36+F36 -> 0
A37: Totals | B37: =SUM(B30:B36) -> 19495702 | C37: =SUM(C30:C36) -> 11604.585 | D37: =SUM(D30:D36) -> 8540126.6 | E37: =SUM(E30:E36) -> 5337.5791 | F37: =SUM(F30:F36) -> 3175597.6 | G37: =SUM(G30:G36) -> 3175.5976 | H37: =SUM(H30:H36) -> 31211427

Sheet Dashboard
A1: 2026 PRODUCTION DASHBOARD
A4: Total Production | D4: Best Month | G4: Average Monthly Production | J4: Top Product
A8: ='Year-2026'!J15 -> 1867724 | D8: June | G8: =A8/7 -> 266817.71 | J8: CHB 8''(20)

Sheet Master Data
A1: Date | B1: Month | C1: Day | D1: CHB 4" | E1: CHB 6" | F1: CHB 8" | G1: HORDI 8" | H1: INS 8" | I1: HORDI 10" | J1: CHB30 | K1: INS 30 CM | L1: Total | M1: Remarks
A2: =DATE(2026,1,C2) -> 46023 | B2: =TEXT(A2,"mmm") -> Jan | C2: 1 | D2: 16060 | L2: =SUM(D2:K2) -> 16060 | P2: Total Production | Q2: =SUM(L2:L213) -> 1867724 | S2: Month | T2: Total Production
A3: =DATE(2026,1,C3) -> 46024 | B3: =TEXT(A3,"mmm") -> Jan | C3: 2 | L3: =SUM(D3:K3) -> 0 | M3: Friday | P3: Production Days | Q3: =COUNTIF(L2:L213,">0") -> 171 | S3: January | T3: =SUMIF($B$2:$B$213,LEFT(S3,3),$L$2:$L$213) -> 272618
A4: =DATE(2026,1,C4) -> 46025 | B4: =TEXT(A4,"mmm") -> Jan | C4: 3 | E4: 4240 | F4: 8160 | L4: =SUM(D4:K4) -> 12400 | P4: Zero-Production Days | Q4: 41 | S4: February | T4: =SUMIF($B$2:$B$213,LEFT(S4,3),$L$2:$L$213) -> 266102
A5: =DATE(2026,1,C5) -> 46026 | B5: =TEXT(A5,"mmm") -> Jan | C5: 4 | E5: 8800 | F5: 3852 | L5: =SUM(D5:K5) -> 12652 | P5: Average Production / Production Day | Q5: =Q2/Q3 -> 10922.363 | S5: March | T5: =SUMIF($B$2:$B$213,LEFT(S5,3),$L$2:$L$213) -> 217024
A6: =DATE(2026,1,C6) -> 46027 | B6: =TEXT(A6,"mmm") -> Jan | C6: 5 | E6: 5120 | F6: 8160 | L6: =SUM(D6:K6) -> 13280 | S6: April | T6: =SUMIF($B$2:$B$213,LEFT(S6,3),$L$2:$L$213) -> 259084
A7: =DATE(2026,1,C7) -> 46028 | B7: =TEXT(A7,"mmm") -> Jan | C7: 6 | F7: 8340 | L7: =SUM(D7:K7) -> 8340 | S7: May | T7: =SUMIF($B$2:$B$213,LEFT(S7,3),$L$2:$L$213) -> 268222
A8: =DATE(2026,1,C8) -> 46029 | B8: =TEXT(A8,"mmm") -> Jan | C8: 7 | F8: 8280 | L8: =SUM(D8:K8) -> 8280 | S8: June | T8: =SUMIF($B$2:$B$213,LEFT(S8,3),$L$2:$L$213) -> 316664
A9: =DATE(2026,1,C9) -> 46030 | B9: =TEXT(A9,"mmm") -> Jan | C9: 8 | F9: 7740 | L9: =SUM(D9:K9) -> 7740 | S9: July | T9: =SUMIF($B$2:$B$213,LEFT(S9,3),$L$2:$L$213) -> 268010
A10: =DATE(2026,1,C10) -> 46031 | B10: =TEXT(A10,"mmm") -> Jan | C10: 9 | L10: =SUM(D10:K10) -> 0 | M10: Friday | S10: Average | T10: =AVERAGE(T3:T9) -> 266817.71
A11: =DATE(2026,1,C11) -> 46032 | B11: =TEXT(A11,"mmm") -> Jan | C11: 10 | E11: 11776 | L11: =SUM(D11:K11) -> 11776
A12: =DATE(2026,1,C12) -> 46033 | B12: =TEXT(A12,"mmm") -> Jan | C12: 11 | F12: 8172 | L12: =SUM(D12:K12) -> 8172 | S12: Product | T12: Total Quantity
A13: =DATE(2026,1,C13) -> 46034 | B13: =TEXT(A13,"mmm") -> Jan | C13: 12 | E13: 5040 | F13: 8520 | L13: =SUM(D13:K13) -> 13560 | S13: CHB 4" | T13: =SUM(D2:D213) -> 204952
A14: =DATE(2026,1,C14) -> 46035 | B14: =TEXT(A14,"mmm") -> Jan | C14: 13 | E14: 5424 | F14: 8220 | L14: =SUM(D14:K14) -> 13644 | S14: CHB 6" | T14: =SUM(E2:E213) -> 465904
A15: =DATE(2026,1,C15) -> 46036 | B15: =TEXT(A15,"mmm") -> Jan | C15: 14 | F15: 8244 | L15: =SUM(D15:K15) -> 8244 | S15: CHB 8" | T15: =SUM(F2:F213) -> 1161480
A16: =DATE(2026,1,C16) -> 46037 | B16: =TEXT(A16,"mmm") -> Jan | C16: 15 | D16: 16192 | L16: =SUM(D16:K16) -> 16192 | S16: HORDI 8" | T16: =SUM(G2:G213) -> 9480
A17: =DATE(2026,1,C17) -> 46038 | B17: =TEXT(A17,"mmm") -> Jan | C17: 16 | L17: =SUM(D17:K17) -> 0 | M17: Friday | S17: INS 8" | T17: =SUM(H2:H213) -> 25908
A18: =DATE(2026,1,C18) -> 46039 | B18: =TEXT(A18,"mmm") -> Jan | C18: 17 | F18: 7872 | L18: =SUM(D18:K18) -> 7872 | S18: HORDI 10" | T18: =SUM(I2:I213) -> 0
A19: =DATE(2026,1,C19) -> 46040 | B19: =TEXT(A19,"mmm") -> Jan | C19: 18 | E19: 10640 | L19: =SUM(D19:K19) -> 10640 | S19: CHB30 | T19: =SUM(J2:J213) -> 0
A20: =DATE(2026,1,C20) -> 46041 | B20: =TEXT(A20,"mmm") -> Jan | C20: 19 | F20: 8268 | L20: =SUM(D20:K20) -> 8268 | S20: INS 30 CM | T20: =SUM(K2:K213) -> 0
A21: =DATE(2026,1,C21) -> 46042 | B21: =TEXT(A21,"mmm") -> Jan | C21: 20 | E21: 9440 | L21: =SUM(D21:K21) -> 9440
A22: =DATE(2026,1,C22) -> 46043 | B22: =TEXT(A22,"mmm") -> Jan | C22: 21 | F22: 8400 | L22: =SUM(D22:K22) -> 8400
A23: =DATE(2026,1,C23) -> 46044 | B23: =TEXT(A23,"mmm") -> Jan | C23: 22 | F23: 8580 | L23: =SUM(D23:K23) -> 8580 | S23: Product | T23: Contribution %
A24: =DATE(2026,1,C24) -> 46045 | B24: =TEXT(A24,"mmm") -> Jan | C24: 23 | L24: =SUM(D24:K24) -> 0 | M24: Friday | S24: CHB 4" | T24: =T13/$Q$2 -> 0.10973356
A25: =DATE(2026,1,C25) -> 46046 | B25: =TEXT(A25,"mmm") -> Jan | C25: 24 | F25: 8244 | L25: =SUM(D25:K25) -> 8244 | S25: CHB 6" | T25: =T14/$Q$2 -> 0.24945013
A26: =DATE(2026,1,C26) -> 46047 | B26: =TEXT(A26,"mmm") -> Jan | C26: 25 | E26: 8400 | F26: 3528 | L26: =SUM(D26:K26) -> 11928 | S26: CHB 8" | T26: =T15/$Q$2 -> 0.62186918
A27: =DATE(2026,1,C27) -> 46048 | B27: =TEXT(A27,"mmm") -> Jan | C27: 26 | F27: 8400 | L27: =SUM(D27:K27) -> 8400 | S27: HORDI 8" | T27: =T16/$Q$2 -> 0.0050756964
A28: =DATE(2026,1,C28) -> 46049 | B28: =TEXT(A28,"mmm") -> Jan | C28: 27 | F28: 8220 | L28: =SUM(D28:K28) -> 8220 | S28: INS 8" | T28: =T17/$Q$2 -> 0.013871429
A29: =DATE(2026,1,C29) -> 46050 | B29: =TEXT(A29,"mmm") -> Jan | C29: 28 | E29: 10160 | L29: =SUM(D29:K29) -> 10160 | S29: HORDI 10" | T29: =T18/$Q$2 -> 0
A30: =DATE(2026,1,C30) -> 46051 | B30: =TEXT(A30,"mmm") -> Jan | C30: 29 | D30: 13750 | L30: =SUM(D30:K30) -> 13750 | S30: CHB30 | T30: =T19/$Q$2 -> 0
A31: =DATE(2026,1,C31) -> 46052 | B31: =TEXT(A31,"mmm") -> Jan | C31: 30 | L31: =SUM(D31:K31) -> 0 | M31: Friday | S31: INS 30 CM | T31: =T20/$Q$2 -> 0
A32: =DATE(2026,1,C32) -> 46053 | B32: =TEXT(A32,"mmm") -> Jan | C32: 31 | F32: 8376 | L32: =SUM(D32:K32) -> 8376
A33: =DATE(2026,2,C33) -> 46054 | B33: =TEXT(A33,"mmm") -> Feb | C33: 1 | E33: 11872 | L33: =SUM(D33:K33) -> 11872
A34: =DATE(2026,2,C34) -> 46055 | B34: =TEXT(A34,"mmm") -> Feb | C34: 2 | F34: 8028 | L34: =SUM(D34:K34) -> 8028 | S34: Product | T34: Contribution %
A35: =DATE(2026,2,C35) -> 46056 | B35: =TEXT(A35,"mmm") -> Feb | C35: 3 | E35: 5040 | F35: 8208 | L35: =SUM(D35:K35) -> 13248 | S35: CHB 4" | T35: 0.1097
A36: =DATE(2026,2,C36) -> 46057 | B36: =TEXT(A36,"mmm") -> Feb | C36: 4 | F36: 8580 | L36: =SUM(D36:K36) -> 8580 | S36: CHB 6" | T36: 0.2495
A37: =DATE(2026,2,C37) -> 46058 | B37: =TEXT(A37,"mmm") -> Feb | C37: 5 | D37: 16170 | L37: =SUM(D37:K37) -> 16170 | S37: CHB 8" | T37: 0.6219
A38: =DATE(2026,2,C38) -> 46059 | B38: =TEXT(A38,"mmm") -> Feb | C38: 6 | L38: =SUM(D38:K38) -> 0 | M38: Friday | S38: HORDI 8" | T38: 0.0051
A39: =DATE(2026,2,C39) -> 46060 | B39: =TEXT(A39,"mmm") -> Feb | C39: 7 | E39: 1200 | F39: 5520 | L39: =SUM(D39:K39) -> 6720 | S39: INS 8" | T39: 0.0139
A40: =DATE(2026,2,C40) -> 46061 | B40: =TEXT(A40,"mmm") -> Feb | C40: 8 | E40: 6720 | F40: 8832 | L40: =SUM(D40:K40) -> 15552
...

Sheet Portfolio Dashboard
A1: 2026 PRODUCTION ANALYSIS DASHBOARD
A4: Total Production | D4: Production Days | G4: Production-Day Rate | J4: Avg. Production / Day
A5: ='Master Data'!Q2 -> 1867724 | D5: ='Master Data'!Q3 -> 171 | G5: ='Master Data'!Q3/('Master Data'!Q3+'Master Data'!Q4) -> 0.80660377 | J5: ='Master Data'!Q2/'Master Data'!Q3 -> 10922.363
